<?xml version="1.0"?>
<robot name="Y1_1">

  <link name="waist_link">
    <visual>
      <origin xyz="0.0000 0.0000 0.0000" rpy="0.0000 0.0000 0.0000" />
      <geometry>
        <mesh filename="../meshes/waist_link.STL" />
      </geometry>
      <material name="waist_link_mat">
        <color rgba="0.5 0.5 0.5 1.0"/>
      </material>
    </visual>
    <collision>
      <origin xyz="0.0000 0.0000 0.0600" rpy="0.0000 0.0000 0.0000" />
      <geometry>
        <sphere radius="0.0600" />
      </geometry>
    </collision>
    <inertial>
      <origin xyz="0.0013 0.0000 0.0572" rpy="0.0000 0.0000 0.0000" />
      <mass value="1.44414585717254" />
      <inertia ixx="0.0040" ixy="0.0000" ixz="0.0000" iyy="0.0029" iyz="0.0000" izz="0.0027" />
    </inertial>
  </link>

  <link name="waist_yaw_Link">
    <visual>
      <origin xyz="0.0000 0.0000 0.0000" rpy="0.0000 0.0000 0.0000" />
      <geometry>
        <mesh filename="../meshes/waist_yaw_Link.STL" />
      </geometry>
      <material name="waist_yaw_Link_mat">
        <color rgba="0.5 0.5 0.5 1.0"/>
      </material>
    </visual>
    <collision>
      <origin xyz="0.0000 0.0000 0.1500" rpy="0.0000 0.0000 0.0000" />
      <geometry>
        <box size="0.0600 0.1500 0.3000" />
      </geometry>
    </collision>
    <inertial>
      <origin xyz="-0.0048 -0.0001 0.1411" rpy="0.0000 0.0000 0.0000" />
      <mass value="1.76450922077218" />
      <inertia ixx="0.0105" ixy="0.0000" ixz="0.0000" iyy="0.0063" iyz="0.0000" izz="0.0053" />
    </inertial>
  </link>

  <link name="r_shoulder_pitch_Link">
    <visual>
      <origin xyz="0.0000 0.0000 0.0000" rpy="0.0000 0.0000 0.0000" />
      <geometry>
        <mesh filename="../meshes/r_shoulder_pitch_Link.STL" />
      </geometry>
      <material name="r_shoulder_pitch_Link_mat">
        <color rgba="0.5 0.5 0.5 1.0"/>
      </material>
    </visual>
    <inertial>
      <origin xyz="0.0004 -0.0359 -0.0001" rpy="0.0000 0.0000 0.0000" />
      <mass value="0.250510804634253" />
      <inertia ixx="0.0001" ixy="0.0000" ixz="0.0000" iyy="0.0001" iyz="0.0000" izz="0.0001" />
    </inertial>
  </link>

  <link name="r_shoulder_roll_Link">
    <visual>
      <origin xyz="0.0000 0.0000 0.0000" rpy="0.0000 0.0000 0.0000" />
      <geometry>
        <mesh filename="../meshes/r_shoulder_roll_Link.STL" />
      </geometry>
      <material name="r_shoulder_roll_Link_mat">
        <color rgba="0.5 0.5 0.5 1.0"/>
      </material>
    </visual>
    <collision>
      <origin xyz="-0.0250 0.0000 0.0000" rpy="0.0000 1.5700 0.0000" />
      <geometry>
        <cylinder radius="0.0300" length="0.0500" />
      </geometry>
    </collision>
    <inertial>
      <origin xyz="-0.0251 0.0000 -0.0298" rpy="0.0000 0.0000 0.0000" />
      <mass value="0.159086224813347" />
      <inertia ixx="0.0001" ixy="0.0000" ixz="0.0000" iyy="0.0001" iyz="0.0000" izz="0.0001" />
    </inertial>
  </link>

  <link name="r_elbow_yaw_Link">
    <visual>
      <origin xyz="0.0000 0.0000 0.0000" rpy="0.0000 0.0000 0.0000" />
      <geometry>
        <mesh filename="../meshes/r_elbow_yaw_Link.STL" />
      </geometry>
      <material name="r_elbow_yaw_Link_mat">
        <color rgba="0.5 0.5 0.5 1.0"/>
      </material>
    </visual>
    <collision>
      <origin xyz="0.0000 0.0000 -0.0500" rpy="0.0000 0.0000 0.0000" />
      <geometry>
        <cylinder radius="0.0300" length="0.1000" />
      </geometry>
    </collision>
    <inertial>
      <origin xyz="0.0039 -0.0001 -0.0817" rpy="0.0000 0.0000 0.0000" />
      <mass value="0.3905942555809" />
      <inertia ixx="0.0003" ixy="0.0000" ixz="0.0000" iyy="0.0003" iyz="0.0000" izz="0.0002" />
    </inertial>
  </link>

  <link name="r_elbow_pitch_Link">
    <visual>
      <origin xyz="0.0000 0.0000 0.0000" rpy="0.0000 0.0000 0.0000" />
      <geometry>
        <mesh filename="../meshes/r_elbow_pitch_Link.STL" />
      </geometry>
      <material name="r_elbow_pitch_Link_mat">
        <color rgba="0.5 0.5 0.5 1.0"/>
      </material>
    </visual>
    <collision>
      <origin xyz="0.0800 -0.0250 0.0000" rpy="0.0000 1.5700 0.0000" />
      <geometry>
        <cylinder radius="0.0300" length="0.1000" />
      </geometry>
    </collision>
    <inertial>
      <origin xyz="0.0768 -0.0250 0.0001" rpy="0.0000 0.0000 0.0000" />
      <mass value="0.329651420649782" />
      <inertia ixx="0.0001" ixy="0.0000" ixz="0.0000" iyy="0.0007" iyz="0.0000" izz="0.0006" />
    </inertial>
  </link>

  <link name="r_wrist_pitch_Link">
    <visual>
      <origin xyz="0.0000 0.0000 0.0000" rpy="0.0000 0.0000 0.0000" />
      <geometry>
        <mesh filename="../meshes/r_wrist_pitch_Link.STL" />
      </geometry>
      <material name="r_wrist_pitch_Link_mat">
        <color rgba="0.5 0.5 0.5 1.0"/>
      </material>
    </visual>
    <collision>
      <origin xyz="0.0800 -0.0200 0.0000" rpy="0.0000 1.5700 0.0000" />
      <geometry>
        <cylinder radius="0.0300" length="0.0800" />
      </geometry>
    </collision>
    <inertial>
      <origin xyz="0.0741 -0.0139 0.0000" rpy="0.0000 0.0000 0.0000" />
      <mass value="0.25366914834894" />
      <inertia ixx="0.0001" ixy="0.0000" ixz="0.0000" iyy="0.0003" iyz="0.0000" izz="0.0003" />
    </inertial>
  </link>

  <link name="l_shoulder_pitch_Link">
    <visual>
      <origin xyz="0.0000 0.0000 0.0000" rpy="0.0000 0.0000 0.0000" />
      <geometry>
        <mesh filename="../meshes/l_shoulder_pitch_Link.STL" />
      </geometry>
      <material name="l_shoulder_pitch_Link_mat">
        <color rgba="0.5 0.5 0.5 1.0"/>
      </material>
    </visual>
    <inertial>
      <origin xyz="0.0004 0.0358 -0.0001" rpy="0.0000 0.0000 0.0000" />
      <mass value="0.25051075276901" />
      <inertia ixx="0.0001" ixy="0.0000" ixz="0.0000" iyy="0.0001" iyz="0.0000" izz="0.0001" />
    </inertial>
  </link>

  <link name="l_shoulder_roll_Link">
    <visual>
      <origin xyz="0.0000 0.0000 0.0000" rpy="0.0000 0.0000 0.0000" />
      <geometry>
        <mesh filename="../meshes/l_shoulder_roll_Link.STL" />
      </geometry>
      <material name="l_shoulder_roll_Link_mat">
        <color rgba="0.5 0.5 0.5 1.0"/>
      </material>
    </visual>
    <collision>
      <origin xyz="-0.0250 0.0000 0.0000" rpy="0.0000 1.5700 0.0000" />
      <geometry>
        <cylinder radius="0.0300" length="0.0500" />
      </geometry>
    </collision>
    <inertial>
      <origin xyz="-0.0251 0.0000 -0.0298" rpy="0.0000 0.0000 0.0000" />
      <mass value="0.159086224813347" />
      <inertia ixx="0.0001" ixy="0.0000" ixz="0.0000" iyy="0.0001" iyz="0.0000" izz="0.0001" />
    </inertial>
  </link>

  <link name="l_elbow_yaw_Link">
    <visual>
      <origin xyz="0.0000 0.0000 0.0000" rpy="0.0000 0.0000 0.0000" />
      <geometry>
        <mesh filename="../meshes/l_elbow_yaw_Link.STL" />
      </geometry>
      <material name="l_elbow_yaw_Link_mat">
        <color rgba="0.5 0.5 0.5 1.0"/>
      </material>
    </visual>
    <collision>
      <origin xyz="0.0000 0.0000 -0.0500" rpy="0.0000 0.0000 0.0000" />
      <geometry>
        <cylinder radius="0.0300" length="0.1000" />
      </geometry>
    </collision>
    <inertial>
      <origin xyz="0.0039 0.0001 -0.0819" rpy="0.0000 0.0000 0.0000" />
      <mass value="0.388621207536409" />
      <inertia ixx="0.0003" ixy="0.0000" ixz="0.0000" iyy="0.0003" iyz="0.0000" izz="0.0002" />
    </inertial>
  </link>

  <link name="l_elbow_pitch_Link">
    <visual>
      <origin xyz="0.0000 0.0000 0.0000" rpy="0.0000 0.0000 0.0000" />
      <geometry>
        <mesh filename="../meshes/l_elbow_pitch_Link.STL" />
      </geometry>
      <material name="l_elbow_pitch_Link_mat">
        <color rgba="0.5 0.5 0.5 1.0"/>
      </material>
    </visual>
    <collision>
      <origin xyz="0.0800 0.0250 0.0000" rpy="0.0000 1.5700 0.0000" />
      <geometry>
        <cylinder radius="0.0300" length="0.1000" />
      </geometry>
    </collision>
    <inertial>
      <origin xyz="0.0770 0.0250 0.0001" rpy="0.0000 0.0000 0.0000" />
      <mass value="0.329651317686521" />
      <inertia ixx="0.0001" ixy="0.0000" ixz="0.0000" iyy="0.0007" iyz="0.0000" izz="0.0006" />
    </inertial>
  </link>

  <link name="l_wrist_pitch_Link">
    <visual>
      <origin xyz="0.0000 0.0000 0.0000" rpy="0.0000 0.0000 0.0000" />
      <geometry>
        <mesh filename="../meshes/l_wrist_pitch_Link.STL" />
      </geometry>
      <material name="l_wrist_pitch_Link_mat">
        <color rgba="0.5 0.5 0.5 1.0"/>
      </material>
    </visual>
    <collision>
      <origin xyz="0.0800 0.0200 0.0000" rpy="0.0000 1.5700 0.0000" />
      <geometry>
        <cylinder radius="0.0300" length="0.0800" />
      </geometry>
    </collision>
    <inertial>
      <origin xyz="0.0741 0.0139 0.0000" rpy="0.0000 0.0000 0.0000" />
      <mass value="0.25366914834894" />
      <inertia ixx="0.0001" ixy="0.0000" ixz="0.0000" iyy="0.0003" iyz="0.0000" izz="0.0003" />
    </inertial>
  </link>

  <link name="l_hip_pitch_Link">
    <visual>
      <origin xyz="0.0000 0.0000 0.0000" rpy="0.0000 0.0000 0.0000" />
      <geometry>
        <mesh filename="../meshes/l_hip_pitch_Link.STL" />
      </geometry>
      <material name="l_hip_pitch_Link_mat">
        <color rgba="0.5 0.5 0.5 1.0"/>
      </material>
    </visual>
    <collision>
      <origin xyz="0.0000 -0.0050 -0.0600" rpy="0.0000 1.5700 0.0000" />
      <geometry>
        <cylinder radius="0.0400" length="0.0500" />
      </geometry>
    </collision>
    <inertial>
      <origin xyz="0.0027 -0.0001 -0.0452" rpy="0.0000 0.0000 0.0000" />
      <mass value="0.369251528004756" />
      <inertia ixx="0.0005" ixy="0.0000" ixz="0.0000" iyy="0.0003" iyz="0.0000" izz="0.0003" />
    </inertial>
  </link>

  <link name="l_hip_roll_Link">
    <visual>
      <origin xyz="0.0000 0.0000 0.0000" rpy="0.0000 0.0000 0.0000" />
      <geometry>
        <mesh filename="../meshes/l_hip_roll_Link.STL" />
      </geometry>
      <material name="l_hip_roll_Link_mat">
        <color rgba="0.5 0.5 0.5 1.0"/>
      </material>
    </visual>
    <collision>
      <origin xyz="0.0000 0.0000 -0.0800" rpy="0.0000 0.0000 0.0000" />
      <geometry>
        <cylinder radius="0.0500" length="0.0400" />
      </geometry>
    </collision>
    <inertial>
      <origin xyz="0.0113 0.0000 -0.0557" rpy="0.0000 0.0000 0.0000" />
      <mass value="0.74464439636084" />
      <inertia ixx="0.0017" ixy="0.0000" ixz="0.0001" iyy="0.0014" iyz="0.0000" izz="0.0010" />
    </inertial>
  </link>

  <link name="l_hip_yaw_Link">
    <visual>
      <origin xyz="0.0000 0.0000 0.0000" rpy="0.0000 0.0000 0.0000" />
      <geometry>
        <mesh filename="../meshes/l_hip_yaw_Link.STL" />
      </geometry>
      <material name="l_hip_yaw_Link_mat">
        <color rgba="0.5 0.5 0.5 1.0"/>
      </material>
    </visual>
    <collision>
      <origin xyz="0.0000 0.0000 -0.0400" rpy="0.0000 0.0000 0.0000" />
      <geometry>
        <cylinder radius="0.0400" length="0.0600" />
      </geometry>
    </collision>
    <inertial>
      <origin xyz="-0.0101 -0.0009 -0.0835" rpy="0.0000 0.0000 0.0000" />
      <mass value="1.0973721550832" />
      <inertia ixx="0.0023" ixy="0.0000" ixz="0.0002" iyy="0.0031" iyz="-0.0001" izz="0.0013" />
    </inertial>
  </link>

  <link name="l_knee_pitch_Link">
    <visual>
      <origin xyz="0.0000 0.0000 0.0000" rpy="0.0000 0.0000 0.0000" />
      <geometry>
        <mesh filename="../meshes/l_knee_pitch_Link.STL" />
      </geometry>
      <material name="l_knee_pitch_Link_mat">
        <color rgba="0.5 0.5 0.5 1.0"/>
      </material>
    </visual>
    <collision>
      <origin xyz="0.0300 -0.0250 -0.1000" rpy="0.0000 0.0000 0.0000" />
      <geometry>
        <cylinder radius="0.0300" length="0.1500" />
      </geometry>
    </collision>
    <inertial>
      <origin xyz="0.0217 -0.0238 -0.0861" rpy="0.0000 0.0000 0.0000" />
      <mass value="0.915276379150789" />
      <inertia ixx="0.0035" ixy="0.0000" ixz="-0.0001" iyy="0.0041" iyz="0.0000" izz="0.0007" />
    </inertial>
  </link>

  <link name="l_ankle_pitch_Link">
    <visual>
      <origin xyz="0.0000 0.0000 0.0000" rpy="0.0000 0.0000 0.0000" />
      <geometry>
        <mesh filename="../meshes/l_ankle_pitch_Link.STL" />
      </geometry>
      <material name="l_ankle_pitch_Link_mat">
        <color rgba="0.5 0.5 0.5 1.0"/>
      </material>
    </visual>
    <inertial>
      <origin xyz="0.0013 -0.0190 -0.0005" rpy="0.0000 0.0000 0.0000" />
      <mass value="0.0432393466754992" />
      <inertia ixx="0.000001" ixy="0.0000" ixz="0.0000" iyy="0.000001" iyz="0.0000" izz="0.000001" />
    </inertial>
  </link>

  <link name="l_ankle_roll_Link">
    <visual>
      <origin xyz="0.0000 0.0000 0.0000" rpy="0.0000 0.0000 0.0000" />
      <geometry>
        <mesh filename="../meshes/l_ankle_roll_Link.STL" />
      </geometry>
      <material name="l_ankle_roll_Link_mat">
        <color rgba="0.5 0.5 0.5 1.0"/>
      </material>
    </visual>
    <!-- <collision>
      <origin xyz="0.0000 0.0000 0.0000" rpy="0.0000 0.0000 0.0000" />
      <geometry>
        <mesh filename="../meshes/l_ankle_roll_Link.STL" />
      </geometry>
    </collision> -->
    <collision>
      <origin xyz="-0.03 0.0000 -0.04" rpy="0.0000 0.0000 0.0000" />
      <geometry>
        <box size="0.18 0.1 0.01" />
      </geometry>
    </collision>
    <inertial>
      <origin xyz="-0.0483 0.0002 -0.0191" rpy="0.0000 0.0000 0.0000" />
      <mass value="0.330082839985978" />
      <inertia ixx="0.001" ixy="0.0000" ixz="0.0000" iyy="0.001" iyz="0.0000" izz="0.002" />
    </inertial>
  </link>


  <joint name="waist_yaw_joint" type="fixed">
    <parent link="waist_link" />
    <child link="waist_yaw_Link" />
    <origin xyz="0.0014 0.0000 0.1350" rpy="0.0000 0.0000 0.0000" />
    <axis xyz="0.0000 0.0000 1.0000" />
    <limit lower="-2.5307274153917776" upper="2.5307274153917776" effort="36.0" velocity="10.5" />
    <hardware>
      <motorType>None</motorType>
      <motorDirection>1</motorDirection>
      <armature>0</armature>
    </hardware>
  </joint>

  <joint name="r_shoulder_pitch_joint" type="fixed">
    <parent link="waist_yaw_Link" />
    <child link="r_shoulder_pitch_Link" />
    <origin xyz="0.0000 -0.0946 0.2310" rpy="-0.2618 0.0000 0.0000" />
    <axis xyz="0.0000 1.0000 0.0000" />
    <limit lower="-2.9670597283903604" upper="2.792526803190927" effort="14.0" velocity="27.2" />
    <hardware>
      <motorType>None</motorType>
      <motorDirection>1</motorDirection>
      <armature>0</armature>
    </hardware>
  </joint>

  <joint name="r_shoulder_roll_joint" type="fixed">
    <parent link="r_shoulder_pitch_Link" />
    <child link="r_shoulder_roll_Link" />
    <origin xyz="0.0265 -0.0475 0.0000" rpy="0.2618 0.0000 0.0000" />
    <axis xyz="1.0000 0.0000 0.0000" />
    <limit lower="-2.2689280275926285" upper="0.17453292519943295" effort="14.0" velocity="27.2" />
    <hardware>
      <motorType>None</motorType>
      <motorDirection>1</motorDirection>
      <armature>0</armature>
    </hardware>
  </joint>

  <joint name="r_elbow_yaw_joint" type="fixed">
    <parent link="r_shoulder_roll_Link" />
    <child link="r_elbow_yaw_Link" />
    <origin xyz="-0.0265 0.0000 -0.0525" rpy="0.0000 0.0000 0.0000" />
    <axis xyz="0.0000 0.0000 1.0000" />
    <limit lower="-2.6179938779914944" upper="2.6179938779914944" effort="14.0" velocity="27.2" />
    <hardware>
      <motorType>None</motorType>
      <motorDirection>1</motorDirection>
      <armature>0</armature>
    </hardware>
  </joint>

  <joint name="r_elbow_pitch_joint" type="fixed">
    <parent link="r_elbow_yaw_Link" />
    <child link="r_elbow_pitch_Link" />
    <origin xyz="0.0100 0.0265 -0.1330" rpy="0.0000 0.0000 0.0000" />
    <axis xyz="0.0000 1.0000 0.0000" />
    <limit lower="-1.0471975511965976" upper="2.5307274153917776" effort="14.0" velocity="27.2" />
    <hardware>
      <motorType>None</motorType>
      <motorDirection>1</motorDirection>
      <armature>0</armature>
    </hardware>
  </joint>

  <joint name="r_wrist_pitch_joint" type="fixed">
    <parent link="r_elbow_pitch_Link" />
    <child link="r_wrist_pitch_Link" />
    <origin xyz="0.1200 0.0000 0.0000" rpy="0.0000 0.0000 0.0000" />
    <axis xyz="0.0000 1.0000 0.0000" />
    <limit lower="-1.7453292519943295" upper="1.7453292519943295" effort="14.0" velocity="27.2" />
    <hardware>
      <motorType>None</motorType>
      <motorDirection>1</motorDirection>
      <armature>0</armature>
    </hardware>
  </joint>

  <joint name="l_shoulder_pitch_joint" type="fixed">
    <parent link="waist_yaw_Link" />
    <child link="l_shoulder_pitch_Link" />
    <origin xyz="0.0000 0.0946 0.2310" rpy="0.2618 0.0000 0.0000" />
    <axis xyz="0.0000 1.0000 0.0000" />
    <limit lower="-2.9670597283903604" upper="2.792526803190927" effort="14.0" velocity="27.2" />
    <hardware>
      <motorType>None</motorType>
      <motorDirection>1</motorDirection>
      <armature>0</armature>
    </hardware>
  </joint>

  <joint name="l_shoulder_roll_joint" type="fixed">
    <parent link="l_shoulder_pitch_Link" />
    <child link="l_shoulder_roll_Link" />
    <origin xyz="0.0265 0.0475 0.0000" rpy="-0.2618 0.0000 0.0000" />
    <axis xyz="1.0000 0.0000 0.0000" />
    <limit lower="-0.17453292519943295" upper="2.2689280275926285" effort="14.0" velocity="27.2" />
    <hardware>
      <motorType>None</motorType>
      <motorDirection>1</motorDirection>
      <armature>0</armature>
    </hardware>
  </joint>

  <joint name="l_elbow_yaw_joint" type="fixed">
    <parent link="l_shoulder_roll_Link" />
    <child link="l_elbow_yaw_Link" />
    <origin xyz="-0.0265 0.0000 -0.0525" rpy="0.0000 0.0000 0.0000" />
    <axis xyz="0.0000 0.0000 1.0000" />
    <limit lower="-2.6179938779914944" upper="2.6179938779914944" effort="14.0" velocity="27.2" />
    <hardware>
      <motorType>None</motorType>
      <motorDirection>1</motorDirection>
      <armature>0</armature>
    </hardware>
  </joint>

  <joint name="l_elbow_pitch_joint" type="fixed">
    <parent link="l_elbow_yaw_Link" />
    <child link="l_elbow_pitch_Link" />
    <origin xyz="0.0100 -0.0265 -0.1330" rpy="0.0000 0.0000 0.0000" />
    <axis xyz="0.0000 1.0000 0.0000" />
    <limit lower="-1.0471975511965976" upper="2.5307274153917776" effort="14.0" velocity="27.2" />
    <hardware>
      <motorType>None</motorType>
      <motorDirection>1</motorDirection>
      <armature>0</armature>
    </hardware>
  </joint>

  <joint name="l_wrist_pitch_joint" type="fixed">
    <parent link="l_elbow_pitch_Link" />
    <child link="l_wrist_pitch_Link" />
    <origin xyz="0.1200 0.0000 0.0000" rpy="0.0000 0.0000 0.0000" />
    <axis xyz="0.0000 1.0000 0.0000" />
    <limit lower="-1.7453292519943295" upper="1.7453292519943295" effort="14.0" velocity="27.2" />
    <hardware>
      <motorType>None</motorType>
      <motorDirection>1</motorDirection>
      <armature>0</armature>
    </hardware>
  </joint>


  <joint name="l_hip_pitch_joint" type="revolute">
    <parent link="waist_link" />
    <child link="l_hip_pitch_Link" />
    <origin xyz="0.0014 0.0654 0.0454" rpy="1.3090 0.0000 0.0000" />
    <axis xyz="0.0000 0.0000 1.0000" />
    <limit lower="-2.5307274153917776" upper="2.8797932657906435" effort="60.0" velocity="18.84" />
    <hardware>
      <motorType>None</motorType>
      <motorDirection>1</motorDirection>
      <armature>0</armature>
    </hardware>
  </joint>

  <joint name="l_hip_roll_joint" type="revolute">
    <parent link="l_hip_pitch_Link" />
    <child link="l_hip_roll_Link" />
    <origin xyz="0.0177 0.0000 -0.0586" rpy="-1.3090 0.0000 0.0000" />
    <axis xyz="1.0000 0.0000 0.0000" />
    <limit lower="-0.2617993877991494" upper="2.792526803190927" effort="36.0" velocity="10.5" />
    <hardware>
      <motorType>None</motorType>
      <motorDirection>1</motorDirection>
      <armature>0</armature>
    </hardware>
  </joint>

  <joint name="l_hip_yaw_joint" type="revolute">
    <parent link="l_hip_roll_Link" />
    <child link="l_hip_yaw_Link" />
    <origin xyz="-0.0027 0.0000 -0.0995" rpy="0.0000 0.0000 0.0000" />
    <axis xyz="0.0000 0.0000 1.0000" />
    <limit lower="-2.792526803190927" upper="2.792526803190927" effort="36.0" velocity="10.5" />
    <hardware>
      <motorType>None</motorType>
      <motorDirection>1</motorDirection>
      <armature>0</armature>
    </hardware>
  </joint>

  <joint name="l_knee_pitch_joint" type="revolute">
    <parent link="l_hip_yaw_Link" />
    <child link="l_knee_pitch_Link" />
    <origin xyz="-0.0300 0.0265 -0.1350" rpy="0.0000 0.0000 0.0000" />
    <axis xyz="0.0000 1.0000 0.0000" />
    <limit lower="-0.08726646259971647" upper="2.792526803190927" effort="60.0" velocity="18.84" />
    <hardware>
      <motorType>None</motorType>
      <motorDirection>1</motorDirection>
      <armature>0</armature>
    </hardware>
  </joint>

  <joint name="l_ankle_pitch_joint" type="revolute">
    <parent link="l_knee_pitch_Link" />
    <child link="l_ankle_pitch_Link" />
    <origin xyz="0.0150 -0.0075 -0.2250" rpy="0.0000 0.0000 0.0000" />
    <axis xyz="0.0000 1.0000 0.0000" />
    <limit lower="-0.8726646259971648" upper="0.3455751918948773" effort="36.0" velocity="10.5" />
    <hardware>
      <motorType>None</motorType>
      <motorDirection>1</motorDirection>
      <armature>0</armature>
    </hardware>
  </joint>

  <joint name="l_ankle_roll_joint" type="revolute">
    <parent link="l_ankle_pitch_Link" />
    <child link="l_ankle_roll_Link" />
    <origin xyz="0.0365 -0.0190 0.0000" rpy="0.0000 0.0000 0.0000" />
    <axis xyz="1.0000 0.0000 0.0000" />
    <limit lower="-0.3455751918948773" upper="0.3455751918948773" effort="14.0" velocity="27.2" />
    <hardware>
      <motorType>None</motorType>
      <motorDirection>1</motorDirection>
      <armature>0</armature>
    </hardware>
  </joint>


</robot>