<?xml version="1.0"?>
<robot name="Y1_1">

  <link name="l_hip_roll_Link">
    <visual>
      <origin xyz="0.0000 0.0000 0.0000" rpy="0.0000 0.0000 0.0000" />
      <geometry>
        <mesh filename="../meshes/l_hip_roll_Link.STL" />
      </geometry>
      <material name="l_hip_roll_Link_mat">
        <color rgba="0.5 0.5 0.5 1.0"/>
      </material>
    </visual>
    <collision>
      <origin xyz="0.0000 0.0000 -0.0800" rpy="0.0000 0.0000 0.0000" />
      <geometry>
        <cylinder radius="0.0500" length="0.0400" />
      </geometry>
    </collision>
    <inertial>
      <origin xyz="0.0113 0.0000 -0.0557" rpy="0.0000 0.0000 0.0000" />
      <mass value="1.0" />
      <inertia ixx="0.0017" ixy="0.0000" ixz="0.0001" iyy="0.0014" iyz="0.0000" izz="0.0010" />
    </inertial>
  </link>

  <link name="l_hip_yaw_Link">
    <visual>
      <origin xyz="0.0000 0.0000 0.0000" rpy="0.0000 0.0000 0.0000" />
      <geometry>
        <mesh filename="../meshes/l_hip_yaw_Link.STL" />
      </geometry>
      <material name="l_hip_yaw_Link_mat">
        <color rgba="0.5 0.5 0.5 1.0"/>
      </material>
    </visual>
    <collision>
      <origin xyz="0.0000 0.0000 -0.0400" rpy="0.0000 0.0000 0.0000" />
      <geometry>
        <cylinder radius="0.0400" length="0.0600" />
      </geometry>
    </collision>
    <inertial>
      <origin xyz="-0.0101 -0.0009 -0.0835" rpy="0.0000 0.0000 0.0000" />
      <mass value="1.5" />
      <inertia ixx="0.0023" ixy="0.0000" ixz="0.0002" iyy="0.0031" iyz="-0.0001" izz="0.0013" />
    </inertial>
  </link>

  <joint name="l_hip_yaw_joint" type="revolute">
    <parent link="l_hip_roll_Link" />
    <child link="l_hip_yaw_Link" />
    <origin xyz="-0.0027 0.0000 -0.0995" rpy="0.0000 0.0000 0.0000" />
    <axis xyz="0.0000 0.0000 1.0000" />
    <limit lower="-2.792526803190927" upper="2.792526803190927" effort="36.0" velocity="10.5" />
    <hardware>
      <motorType>None</motorType>
      <motorDirection>1</motorDirection>
      <armature>0</armature>
    </hardware>
  </joint>




</robot>
