<mujoco model="Y1_1">
  <option iterations="50" timestep="0.001" solver="PGS" gravity="0 0 -9.81" />

  <compiler angle="radian" meshdir="../meshes"/>

  <default>
    <joint limited="true" damping="0.01" armature="0.01" frictionloss="0.01" />
    <geom condim="4" contype="1" conaffinity="15" friction="0.9 0.9 0.9" solref="0.001 2" />
    <motor ctrllimited="true" />
    <equality solref="0.001 2" />
    <default class="robot">
      <default class="motor">
        <joint />
        <motor />
      </default>
      <default class="visual">
        <geom material="visualgeom" contype="0" conaffinity="0" group="2" />
      </default>
      <default class="collision">
        <geom material="collision_material" condim="4" contype="0" conaffinity="1" priority="1" group="1" solref="0.001 2" friction="1 0.2 0.01" />
        <equality solimp="0.99 0.999 1e-05" solref="0.005 1" />
      </default>
    </default>
    <default class="visualgeom">
      <geom material="visualgeom" condim="1" contype="0" conaffinity="0" />
    </default>
  </default>

  <asset>
    <material name="waist_link_mat" rgba="0.5 0.5 0.5 1.0" />
    <material name="default_material" rgba="0.7 0.7 0.7 1" />
    <material name="collision_material" rgba="1.0 0.28 0.1 0" />
    <mesh name="waist_link.STL" file="../meshes/waist_link.STL" />
    <mesh name="waist_yaw_Link.STL" file="../meshes/waist_yaw_Link.STL" />
    <mesh name="r_shoulder_pitch_Link.STL" file="../meshes/r_shoulder_pitch_Link.STL" />
    <mesh name="r_shoulder_roll_Link.STL" file="../meshes/r_shoulder_roll_Link.STL" />
    <mesh name="r_elbow_yaw_Link.STL" file="../meshes/r_elbow_yaw_Link.STL" />
    <mesh name="r_elbow_pitch_Link.STL" file="../meshes/r_elbow_pitch_Link.STL" />
    <mesh name="r_wrist_pitch_Link.STL" file="../meshes/r_wrist_pitch_Link.STL" />
    <mesh name="l_shoulder_pitch_Link.STL" file="../meshes/l_shoulder_pitch_Link.STL" />
    <mesh name="l_shoulder_roll_Link.STL" file="../meshes/l_shoulder_roll_Link.STL" />
    <mesh name="l_elbow_yaw_Link.STL" file="../meshes/l_elbow_yaw_Link.STL" />
    <mesh name="l_elbow_pitch_Link.STL" file="../meshes/l_elbow_pitch_Link.STL" />
    <mesh name="l_wrist_pitch_Link.STL" file="../meshes/l_wrist_pitch_Link.STL" />
    <mesh name="r_hip_pitch_Link.STL" file="../meshes/r_hip_pitch_Link.STL" />
    <mesh name="r_hip_roll_Link.STL" file="../meshes/r_hip_roll_Link.STL" />
    <mesh name="r_hip_yaw_Link.STL" file="../meshes/r_hip_yaw_Link.STL" />
    <mesh name="r_knee_pitch_Link.STL" file="../meshes/r_knee_pitch_Link.STL" />
    <mesh name="r_ankle_pitch_Link.STL" file="../meshes/r_ankle_pitch_Link.STL" />
    <mesh name="r_ankle_roll_Link.STL" file="../meshes/r_ankle_roll_Link.STL" />
    <mesh name="l_hip_pitch_Link.STL" file="../meshes/l_hip_pitch_Link.STL" />
    <mesh name="l_hip_roll_Link.STL" file="../meshes/l_hip_roll_Link.STL" />
    <mesh name="l_hip_yaw_Link.STL" file="../meshes/l_hip_yaw_Link.STL" />
    <mesh name="l_knee_pitch_Link.STL" file="../meshes/l_knee_pitch_Link.STL" />
    <mesh name="l_ankle_pitch_Link.STL" file="../meshes/l_ankle_pitch_Link.STL" />
    <mesh name="l_ankle_roll_Link.STL" file="../meshes/l_ankle_roll_Link.STL" />
    <texture name="texplane" type="2d" builtin="checker" rgb1=".0 .0 .0" rgb2=".8 .8 .8" width="100" height="100" />
    <material name="matplane" reflectance="0." texture="texplane" texrepeat="1 1" texuniform="true" />
    <texture type="skybox" builtin="gradient" rgb1="0.3 0.5 0.7" rgb2="0 0 0" width="512"
      height="3072" />
    <texture type="2d" name="groundplane" builtin="checker" mark="edge" rgb1="0.2 0.3 0.4"
      rgb2="0.1 0.2 0.3" markrgb="0.8 0.8 0.8" width="300" height="300" />
    <material name="groundplane" texture="groundplane" texuniform="true" texrepeat="5 5"
      reflectance="0.2" />
  </asset>

  <worldbody>
    <body name="waist_link" pos="0 0 0.45" >
      <freejoint name="floating_base"/>
      <site name="imu" size="0.01" pos="0 0 0.5" />
        <inertial pos="0.0013 0.0000 0.0572" quat="1.0 0.0 0.0 0.0" mass="1.44414585717254" diaginertia="0.004 0.0029 0.0027" />
        <geom name="waist_link_collision" pos="0.0000 0.0000 0.0600" quat="1.0 0.0 0.0 0.0" type="sphere" size="0.0600" class="collision" />
        <geom name="waist_link_visual" pos="0.0000 0.0000 0.0000" quat="1.0 0.0 0.0 0.0" material="waist_link_mat" type="mesh" mesh="waist_link.STL" class="visual" />
        <body name="waist_yaw_Link" pos="0.0014 0.0000 0.1350" quat="1.0 0.0 0.0 0.0">
          <joint name="waist_yaw_joint" type="hinge" ref="0.0" class="motor" limited="true" range="-2.5307274153917776 2.5307274153917776" axis="0.0000 0.0000 1.0000" armature="0.012" />
          <inertial pos="-0.0048 -0.0001 0.1411" quat="1.0 0.0 0.0 0.0" mass="1.76450922077218" diaginertia="0.0105 0.0063 0.0053" />
          <geom name="waist_yaw_Link_collision" pos="0.0000 0.0000 0.1500" quat="1.0 0.0 0.0 0.0" type="box" size="0.03 0.075 0.15" class="collision" />
          <geom name="waist_yaw_Link_visual" pos="0.0000 0.0000 0.0000" quat="1.0 0.0 0.0 0.0" material="waist_link_mat" type="mesh" mesh="waist_yaw_Link.STL" class="visual" />
          <body name="r_shoulder_pitch_Link" pos="0.0000 -0.0946 0.2310" quat="0.991444821419641 -0.1305264957017392 0.0 0.0">
            <joint name="r_shoulder_pitch_joint" type="hinge" ref="0.0" class="motor" limited="true" range="-2.9670597283903604 2.792526803190927" axis="0.0000 1.0000 0.0000" armature="0.001" />
            <inertial pos="0.0004 -0.0359 -0.0001" quat="1.0 0.0 0.0 0.0" mass="0.250510804634253" diaginertia="0.0001 0.0001 0.0001" />
            <geom name="r_shoulder_pitch_Link_visual" pos="0.0000 0.0000 0.0000" quat="1.0 0.0 0.0 0.0" material="waist_link_mat" type="mesh" mesh="r_shoulder_pitch_Link.STL" class="visual" />
            <body name="r_shoulder_roll_Link" pos="0.0265 -0.0475 0.0000" quat="0.991444821419641 0.1305264957017392 0.0 0.0">
              <joint name="r_shoulder_roll_joint" type="hinge" ref="0.0" class="motor" limited="true" range="-2.2689280275926285 0.17453292519943295" axis="1.0000 0.0000 0.0000" armature="0.001" />
              <inertial pos="-0.0251 0.0000 -0.0298" quat="1.0 0.0 0.0 0.0" mass="0.159086224813347" diaginertia="0.0001 0.0001 0.0001" />
              <geom name="r_shoulder_roll_Link_collision" pos="-0.0250 0.0000 0.0000" quat="0.7073882691671998 0.0 0.706825181105366 0.0" type="cylinder" size="0.0300 0.025" class="collision" />
              <geom name="r_shoulder_roll_Link_visual" pos="0.0000 0.0000 0.0000" quat="1.0 0.0 0.0 0.0" material="waist_link_mat" type="mesh" mesh="r_shoulder_roll_Link.STL" class="visual" />
              <body name="r_elbow_yaw_Link" pos="-0.0265 0.0000 -0.0525" quat="1.0 0.0 0.0 0.0">
                <joint name="r_elbow_yaw_joint" type="hinge" ref="0.0" class="motor" limited="true" range="-2.6179938779914944 2.6179938779914944" axis="0.0000 0.0000 1.0000" armature="0.001" />
                <inertial pos="0.0039 -0.0001 -0.0817" quat="1.0 0.0 0.0 0.0" mass="0.3905942555809" diaginertia="0.0003 0.0003 0.0002" />
                <geom name="r_elbow_yaw_Link_collision" pos="0.0000 0.0000 -0.0500" quat="1.0 0.0 0.0 0.0" type="cylinder" size="0.0300 0.05" class="collision" />
                <geom name="r_elbow_yaw_Link_visual" pos="0.0000 0.0000 0.0000" quat="1.0 0.0 0.0 0.0" material="waist_link_mat" type="mesh" mesh="r_elbow_yaw_Link.STL" class="visual" />
                <body name="r_elbow_pitch_Link" pos="0.0100 0.0265 -0.1330" quat="1.0 0.0 0.0 0.0">
                  <joint name="r_elbow_pitch_joint" type="hinge" ref="0.0" class="motor" limited="true" range="-1.0471975511965976 2.5307274153917776" axis="0.0000 1.0000 0.0000" armature="0.001" />
                  <inertial pos="0.0768 -0.0250 0.0001" quat="1.0 0.0 0.0 0.0" mass="0.329651420649782" diaginertia="0.0001 0.0007 0.0006" />
                  <geom name="r_elbow_pitch_Link_collision" pos="0.0800 -0.0250 0.0000" quat="0.7073882691671998 0.0 0.706825181105366 0.0" type="cylinder" size="0.0300 0.05" class="collision" />
                  <geom name="r_elbow_pitch_Link_visual" pos="0.0000 0.0000 0.0000" quat="1.0 0.0 0.0 0.0" material="waist_link_mat" type="mesh" mesh="r_elbow_pitch_Link.STL" class="visual" />
                  <body name="r_wrist_pitch_Link" pos="0.1200 0.0000 0.0000" quat="1.0 0.0 0.0 0.0">
                    <joint name="r_wrist_pitch_joint" type="hinge" ref="0.0" class="motor" limited="true" range="-1.7453292519943295 1.7453292519943295" axis="0.0000 1.0000 0.0000" armature="0.001" />
                    <inertial pos="0.0741 -0.0139 0.0000" quat="1.0 0.0 0.0 0.0" mass="0.25366914834894" diaginertia="0.0001 0.0003 0.0003" />
                    <geom name="r_wrist_pitch_Link_collision" pos="0.0800 -0.0200 0.0000" quat="0.7073882691671998 0.0 0.706825181105366 0.0" type="cylinder" size="0.0300 0.04" class="collision" />
                    <geom name="r_wrist_pitch_Link_visual" pos="0.0000 0.0000 0.0000" quat="1.0 0.0 0.0 0.0" material="waist_link_mat" type="mesh" mesh="r_wrist_pitch_Link.STL" class="visual" />
                  </body>
                </body>
              </body>
            </body>
          </body>
          <body name="l_shoulder_pitch_Link" pos="0.0000 0.0946 0.2310" quat="0.991444821419641 0.1305264957017392 0.0 0.0">
            <joint name="l_shoulder_pitch_joint" type="hinge" ref="0.0" class="motor" limited="true" range="-2.9670597283903604 2.792526803190927" axis="0.0000 1.0000 0.0000" armature="0.001" />
            <inertial pos="0.0004 0.0358 -0.0001" quat="1.0 0.0 0.0 0.0" mass="0.25051075276901" diaginertia="0.0001 0.0001 0.0001" />
            <geom name="l_shoulder_pitch_Link_visual" pos="0.0000 0.0000 0.0000" quat="1.0 0.0 0.0 0.0" material="waist_link_mat" type="mesh" mesh="l_shoulder_pitch_Link.STL" class="visual" />
            <body name="l_shoulder_roll_Link" pos="0.0265 0.0475 0.0000" quat="0.991444821419641 -0.1305264957017392 0.0 0.0">
              <joint name="l_shoulder_roll_joint" type="hinge" ref="0.0" class="motor" limited="true" range="-0.17453292519943295 2.2689280275926285" axis="1.0000 0.0000 0.0000" armature="0.001" />
              <inertial pos="-0.0251 0.0000 -0.0298" quat="1.0 0.0 0.0 0.0" mass="0.159086224813347" diaginertia="0.0001 0.0001 0.0001" />
              <geom name="l_shoulder_roll_Link_collision" pos="-0.0250 0.0000 0.0000" quat="0.7073882691671998 0.0 0.706825181105366 0.0" type="cylinder" size="0.0300 0.025" class="collision" />
              <geom name="l_shoulder_roll_Link_visual" pos="0.0000 0.0000 0.0000" quat="1.0 0.0 0.0 0.0" material="waist_link_mat" type="mesh" mesh="l_shoulder_roll_Link.STL" class="visual" />
              <body name="l_elbow_yaw_Link" pos="-0.0265 0.0000 -0.0525" quat="1.0 0.0 0.0 0.0">
                <joint name="l_elbow_yaw_joint" type="hinge" ref="0.0" class="motor" limited="true" range="-2.6179938779914944 2.6179938779914944" axis="0.0000 0.0000 1.0000" armature="0.001" />
                <inertial pos="0.0039 0.0001 -0.0819" quat="1.0 0.0 0.0 0.0" mass="0.388621207536409" diaginertia="0.0003 0.0003 0.0002" />
                <geom name="l_elbow_yaw_Link_collision" pos="0.0000 0.0000 -0.0500" quat="1.0 0.0 0.0 0.0" type="cylinder" size="0.0300 0.05" class="collision" />
                <geom name="l_elbow_yaw_Link_visual" pos="0.0000 0.0000 0.0000" quat="1.0 0.0 0.0 0.0" material="waist_link_mat" type="mesh" mesh="l_elbow_yaw_Link.STL" class="visual" />
                <body name="l_elbow_pitch_Link" pos="0.0100 -0.0265 -0.1330" quat="1.0 0.0 0.0 0.0">
                  <joint name="l_elbow_pitch_joint" type="hinge" ref="0.0" class="motor" limited="true" range="-1.0471975511965976 2.5307274153917776" axis="0.0000 1.0000 0.0000" armature="0.001" />
                  <inertial pos="0.0770 0.0250 0.0001" quat="1.0 0.0 0.0 0.0" mass="0.329651317686521" diaginertia="0.0001 0.0007 0.0006" />
                  <geom name="l_elbow_pitch_Link_collision" pos="0.0800 0.0250 0.0000" quat="0.7073882691671998 0.0 0.706825181105366 0.0" type="cylinder" size="0.0300 0.05" class="collision" />
                  <geom name="l_elbow_pitch_Link_visual" pos="0.0000 0.0000 0.0000" quat="1.0 0.0 0.0 0.0" material="waist_link_mat" type="mesh" mesh="l_elbow_pitch_Link.STL" class="visual" />
                  <body name="l_wrist_pitch_Link" pos="0.1200 0.0000 0.0000" quat="1.0 0.0 0.0 0.0">
                    <joint name="l_wrist_pitch_joint" type="hinge" ref="0.0" class="motor" limited="true" range="-1.7453292519943295 1.7453292519943295" axis="0.0000 1.0000 0.0000" armature="0.001" />
                    <inertial pos="0.0741 0.0139 0.0000" quat="1.0 0.0 0.0 0.0" mass="0.25366914834894" diaginertia="0.0001 0.0003 0.0003" />
                    <geom name="l_wrist_pitch_Link_collision" pos="0.0800 0.0200 0.0000" quat="0.7073882691671998 0.0 0.706825181105366 0.0" type="cylinder" size="0.0300 0.04" class="collision" />
                    <geom name="l_wrist_pitch_Link_visual" pos="0.0000 0.0000 0.0000" quat="1.0 0.0 0.0 0.0" material="waist_link_mat" type="mesh" mesh="l_wrist_pitch_Link.STL" class="visual" />
                  </body>
                </body>
              </body>
            </body>
          </body>
        </body>
        <body name="r_hip_pitch_Link" pos="0.0014 -0.0654 0.0454" quat="0.7933524085796444 -0.6087626432369819 0.0 0.0">
          <joint name="r_hip_pitch_joint" type="hinge" ref="0.0" class="motor" limited="true" range="-2.5307274153917776 2.8797932657906435" axis="0.0000 0.0000 1.0000" armature="0.02" />
          <inertial pos="0.0027 0.0001 -0.0452" quat="1.0 0.0 0.0 0.0" mass="0.369252030694756" diaginertia="0.0005 0.0003 0.0003" />
          <geom name="r_hip_pitch_Link_collision" pos="0.0000 0.0050 -0.0600" quat="0.7073882691671998 0.0 0.706825181105366 0.0" type="cylinder" size="0.0400 0.025" class="collision" />
          <geom name="r_hip_pitch_Link_visual" pos="0.0000 0.0000 0.0000" quat="1.0 0.0 0.0 0.0" material="waist_link_mat" type="mesh" mesh="r_hip_pitch_Link.STL" class="visual" />
          <body name="r_hip_roll_Link" pos="0.0177 0.0000 -0.0586" quat="0.7933524085796444 0.6087626432369819 0.0 0.0">
            <joint name="r_hip_roll_joint" type="hinge" ref="0.0" class="motor" limited="true" range="-2.792526803190927 0.2617993877991494" axis="1.0000 0.0000 0.0000" armature="0.012" />
            <inertial pos="0.0113 0.0000 -0.0557" quat="1.0 0.0 0.0 0.0" mass="0.744644396415213" diaginertia="0.0017 0.0014 0.001" />
            <geom name="r_hip_roll_Link_collision" pos="0.0000 0.0000 -0.0800" quat="1.0 0.0 0.0 0.0" type="cylinder" size="0.0500 0.02" class="collision" />
            <geom name="r_hip_roll_Link_visual" pos="0.0000 0.0000 0.0000" quat="1.0 0.0 0.0 0.0" material="waist_link_mat" type="mesh" mesh="r_hip_roll_Link.STL" class="visual" />
            <body name="r_hip_yaw_Link" pos="-0.0027 0.0000 -0.0995" quat="1.0 0.0 0.0 0.0">
              <joint name="r_hip_yaw_joint" type="hinge" ref="0.0" class="motor" limited="true" range="-2.792526803190927 2.792526803190927" axis="0.0000 0.0000 1.0000" armature="0.012" />
              <inertial pos="-0.0101 0.0009 -0.0835" quat="1.0 0.0 0.0 0.0" mass="1.09737363524428" diaginertia="0.0023 0.0031 0.0013" />
              <geom name="r_hip_yaw_Link_collision" pos="0.0000 0.0000 -0.0400" quat="1.0 0.0 0.0 0.0" type="cylinder" size="0.0400 0.03" class="collision" />
              <geom name="r_hip_yaw_Link_visual" pos="0.0000 0.0000 0.0000" quat="1.0 0.0 0.0 0.0" material="waist_link_mat" type="mesh" mesh="r_hip_yaw_Link.STL" class="visual" />
              <body name="r_knee_pitch_Link" pos="-0.0300 -0.0265 -0.1350" quat="1.0 0.0 0.0 0.0">
                <joint name="r_knee_pitch_joint" type="hinge" ref="0.0" class="motor" limited="true" range="-0.08726646259971647 2.792526803190927" axis="0.0000 1.0000 0.0000" armature="0.02" />
                <inertial pos="0.0217 0.0238 -0.0867" quat="1.0 0.0 0.0 0.0" mass="0.916781990636595" diaginertia="0.0035 0.0041 0.0007" />
                <geom name="r_knee_pitch_Link_collision" pos="0.0300 0.0250 -0.1000" quat="1.0 0.0 0.0 0.0" type="cylinder" size="0.0300 0.075" class="collision" />
                <geom name="r_knee_pitch_Link_visual" pos="0.0000 0.0000 0.0000" quat="1.0 0.0 0.0 0.0" material="waist_link_mat" type="mesh" mesh="r_knee_pitch_Link.STL" class="visual" />
                <body name="r_ankle_pitch_Link" pos="0.0150 0.0075 -0.2250" quat="1.0 0.0 0.0 0.0">
                  <joint name="r_ankle_pitch_joint" type="hinge" ref="0.0" class="motor" limited="true" range="-0.8726646259971648 0.3455751918948773" axis="0.0000 1.0000 0.0000" armature="0.012" />
                  <inertial pos="0.0013 0.0190 -0.0005" quat="1.0 0.0 0.0 0.0" mass="0.0432393466754992" diaginertia="0.000001 0.000001 0.000001" />
                  <geom name="r_ankle_pitch_Link_visual" pos="0.0000 0.0000 0.0000" quat="1.0 0.0 0.0 0.0" material="waist_link_mat" type="mesh" mesh="r_ankle_pitch_Link.STL" class="visual" />
                  <body name="r_ankle_roll_Link" pos="0.0365 0.0190 0.0000" quat="1.0 0.0 0.0 0.0">
                    <joint name="r_ankle_roll_joint" type="hinge" ref="0.0" class="motor" limited="true" range="-0.3455751918948773 0.3455751918948773" axis="1.0000 0.0000 0.0000" armature="0.001" />
                    <inertial pos="-0.0436 0.0001 -0.0227" quat="1.0 0.0 0.0 0.0" mass="0.330082839985978" diaginertia="0.001 0.001 0.001" />
                    <geom name="r_ankle_roll_Link_collision" pos="-0.03 0.0000 -0.04" quat="1.0 0.0 0.0 0.0" type="box" size="0.09 0.05 0.005" class="collision" />
                    <geom name="r_ankle_roll_Link_visual" pos="0.0000 0.0000 0.0000" quat="1.0 0.0 0.0 0.0" material="waist_link_mat" type="mesh" mesh="r_ankle_roll_Link.STL" class="visual" />
                  </body>
                </body>
              </body>
            </body>
          </body>
        </body>
        <body name="l_hip_pitch_Link" pos="0.0014 0.0654 0.0454" quat="0.7933524085796444 0.6087626432369819 0.0 0.0">
          <joint name="l_hip_pitch_joint" type="hinge" ref="0.0" class="motor" limited="true" range="-2.5307274153917776 2.8797932657906435" axis="0.0000 0.0000 1.0000" armature="0.02" />
          <inertial pos="0.0027 -0.0001 -0.0452" quat="1.0 0.0 0.0 0.0" mass="0.369251528004756" diaginertia="0.0005 0.0003 0.0003" />
          <geom name="l_hip_pitch_Link_collision" pos="0.0000 -0.0050 -0.0600" quat="0.7073882691671998 0.0 0.706825181105366 0.0" type="cylinder" size="0.0400 0.025" class="collision" />
          <geom name="l_hip_pitch_Link_visual" pos="0.0000 0.0000 0.0000" quat="1.0 0.0 0.0 0.0" material="waist_link_mat" type="mesh" mesh="l_hip_pitch_Link.STL" class="visual" />
          <body name="l_hip_roll_Link" pos="0.0177 0.0000 -0.0586" quat="0.7933524085796444 -0.6087626432369819 0.0 0.0">
            <joint name="l_hip_roll_joint" type="hinge" ref="0.0" class="motor" limited="true" range="-0.2617993877991494 2.792526803190927" axis="1.0000 0.0000 0.0000" armature="0.012" />
            <inertial pos="0.0113 0.0000 -0.0557" quat="1.0 0.0 0.0 0.0" mass="0.74464439636084" diaginertia="0.0017 0.0014 0.001" />
            <geom name="l_hip_roll_Link_collision" pos="0.0000 0.0000 -0.0800" quat="1.0 0.0 0.0 0.0" type="cylinder" size="0.0500 0.02" class="collision" />
            <geom name="l_hip_roll_Link_visual" pos="0.0000 0.0000 0.0000" quat="1.0 0.0 0.0 0.0" material="waist_link_mat" type="mesh" mesh="l_hip_roll_Link.STL" class="visual" />
            <body name="l_hip_yaw_Link" pos="-0.0027 0.0000 -0.0995" quat="1.0 0.0 0.0 0.0">
              <joint name="l_hip_yaw_joint" type="hinge" ref="0.0" class="motor" limited="true" range="-2.792526803190927 2.792526803190927" axis="0.0000 0.0000 1.0000" armature="0.012" />
              <inertial pos="-0.0101 -0.0009 -0.0835" quat="1.0 0.0 0.0 0.0" mass="1.0973721550832" diaginertia="0.0023 0.0031 0.0013" />
              <geom name="l_hip_yaw_Link_collision" pos="0.0000 0.0000 -0.0400" quat="1.0 0.0 0.0 0.0" type="cylinder" size="0.0400 0.03" class="collision" />
              <geom name="l_hip_yaw_Link_visual" pos="0.0000 0.0000 0.0000" quat="1.0 0.0 0.0 0.0" material="waist_link_mat" type="mesh" mesh="l_hip_yaw_Link.STL" class="visual" />
              <body name="l_knee_pitch_Link" pos="-0.0300 0.0265 -0.1350" quat="1.0 0.0 0.0 0.0">
                <joint name="l_knee_pitch_joint" type="hinge" ref="0.0" class="motor" limited="true" range="0.08726646259971647 2.792526803190927" axis="0.0000 1.0000 0.0000" armature="0.02" />
                <inertial pos="0.0217 -0.0238 -0.0861" quat="1.0 0.0 0.0 0.0" mass="0.915276379150789" diaginertia="0.0035 0.0041 0.0007" />
                <geom name="l_knee_pitch_Link_collision" pos="0.0300 -0.0250 -0.1000" quat="1.0 0.0 0.0 0.0" type="cylinder" size="0.0300 0.075" class="collision" />
                <geom name="l_knee_pitch_Link_visual" pos="0.0000 0.0000 0.0000" quat="1.0 0.0 0.0 0.0" material="waist_link_mat" type="mesh" mesh="l_knee_pitch_Link.STL" class="visual" />
                <body name="l_ankle_pitch_Link" pos="0.0150 -0.0075 -0.2250" quat="1.0 0.0 0.0 0.0">
                  <joint name="l_ankle_pitch_joint" type="hinge" ref="0.0" class="motor" limited="true" range="-0.8726646259971648 0.3455751918948773" axis="0.0000 1.0000 0.0000" armature="0.012" />
                  <inertial pos="0.0013 -0.0190 -0.0005" quat="1.0 0.0 0.0 0.0" mass="0.0432393466754992" diaginertia="0.000001 0.000001 0.000001" />
                  <geom name="l_ankle_pitch_Link_visual" pos="0.0000 0.0000 0.0000" quat="1.0 0.0 0.0 0.0" material="waist_link_mat" type="mesh" mesh="l_ankle_pitch_Link.STL" class="visual" />
                  <body name="l_ankle_roll_Link" pos="0.0365 -0.0190 0.0000" quat="1.0 0.0 0.0 0.0">
                    <joint name="l_ankle_roll_joint" type="hinge" ref="0.0" class="motor" limited="true" range="-0.3455751918948773 0.3455751918948773" axis="1.0000 0.0000 0.0000" armature="0.001" />
                    <inertial pos="-0.0483 0.0002 -0.0191" quat="1.0 0.0 0.0 0.0" mass="0.330082839985978" diaginertia="0.001 0.001 0.001" />
                    <geom name="l_ankle_roll_Link_collision" pos="-0.03 0.0000 -0.04" quat="1.0 0.0 0.0 0.0" type="box" size="0.09 0.05 0.005" class="collision" />
                    <geom name="l_ankle_roll_Link_visual" pos="0.0000 0.0000 0.0000" quat="1.0 0.0 0.0 0.0" material="waist_link_mat" type="mesh" mesh="l_ankle_roll_Link.STL" class="visual" />
                  </body>
                </body>
              </body>
            </body>
          </body>
        </body>
      <site name="world_site" pos="0 0 0" quat="1 0 0 0" />
      <camera name="front_camera" mode="track" fovy="90.0" quat="4.329780281177467e-17 4.329780281177466e-17 0.7071067811865475 0.7071067811865476" pos="0.0 2.0 0.5" />
      <camera name="side_camera" mode="track" fovy="90.0" quat="-0.5 -0.4999999999999999 0.5 0.5000000000000001" pos="-2.0 0.0 0.5" />
    </body>
  </worldbody>

  <actuator>
    <motor name="waist_yaw_joint_ctrl" joint="waist_yaw_joint" class="motor" ctrllimited="true" ctrlrange="-36.0 36.0" gear="1" />
    <motor name="r_shoulder_pitch_joint_ctrl" joint="r_shoulder_pitch_joint" class="motor" ctrllimited="true" ctrlrange="-14.0 14.0" gear="1" />
    <motor name="r_shoulder_roll_joint_ctrl" joint="r_shoulder_roll_joint" class="motor" ctrllimited="true" ctrlrange="-14.0 14.0" gear="1" />
    <motor name="r_elbow_yaw_joint_ctrl" joint="r_elbow_yaw_joint" class="motor" ctrllimited="true" ctrlrange="-14.0 14.0" gear="1" />
    <motor name="r_elbow_pitch_joint_ctrl" joint="r_elbow_pitch_joint" class="motor" ctrllimited="true" ctrlrange="-14.0 14.0" gear="1" />
    <motor name="r_wrist_pitch_joint_ctrl" joint="r_wrist_pitch_joint" class="motor" ctrllimited="true" ctrlrange="-14.0 14.0" gear="1" />
    <motor name="l_shoulder_pitch_joint_ctrl" joint="l_shoulder_pitch_joint" class="motor" ctrllimited="true" ctrlrange="-14.0 14.0" gear="1" />
    <motor name="l_shoulder_roll_joint_ctrl" joint="l_shoulder_roll_joint" class="motor" ctrllimited="true" ctrlrange="-14.0 14.0" gear="1" />
    <motor name="l_elbow_yaw_joint_ctrl" joint="l_elbow_yaw_joint" class="motor" ctrllimited="true" ctrlrange="-14.0 14.0" gear="1" />
    <motor name="l_elbow_pitch_joint_ctrl" joint="l_elbow_pitch_joint" class="motor" ctrllimited="true" ctrlrange="-14.0 14.0" gear="1" />
    <motor name="l_wrist_pitch_joint_ctrl" joint="l_wrist_pitch_joint" class="motor" ctrllimited="true" ctrlrange="-14.0 14.0" gear="1" />
    <motor name="r_hip_pitch_joint_ctrl" joint="r_hip_pitch_joint" class="motor" ctrllimited="true" ctrlrange="-60.0 60.0" gear="1" />
    <motor name="r_hip_roll_joint_ctrl" joint="r_hip_roll_joint" class="motor" ctrllimited="true" ctrlrange="-36.0 36.0" gear="1" />
    <motor name="r_hip_yaw_joint_ctrl" joint="r_hip_yaw_joint" class="motor" ctrllimited="true" ctrlrange="-36.0 36.0" gear="1" />
    <motor name="r_knee_pitch_joint_ctrl" joint="r_knee_pitch_joint" class="motor" ctrllimited="true" ctrlrange="-60.0 60.0" gear="1" />
    <motor name="r_ankle_pitch_joint_ctrl" joint="r_ankle_pitch_joint" class="motor" ctrllimited="true" ctrlrange="-36.0 36.0" gear="1" />
    <motor name="r_ankle_roll_joint_ctrl" joint="r_ankle_roll_joint" class="motor" ctrllimited="true" ctrlrange="-14.0 14.0" gear="1" />
    <motor name="l_hip_pitch_joint_ctrl" joint="l_hip_pitch_joint" class="motor" ctrllimited="true" ctrlrange="-60.0 60.0" gear="1" />
    <motor name="l_hip_roll_joint_ctrl" joint="l_hip_roll_joint" class="motor" ctrllimited="true" ctrlrange="-36.0 36.0" gear="1" />
    <motor name="l_hip_yaw_joint_ctrl" joint="l_hip_yaw_joint" class="motor" ctrllimited="true" ctrlrange="-36.0 36.0" gear="1" />
    <motor name="l_knee_pitch_joint_ctrl" joint="l_knee_pitch_joint" class="motor" ctrllimited="true" ctrlrange="-60.0 60.0" gear="1" />
    <motor name="l_ankle_pitch_joint_ctrl" joint="l_ankle_pitch_joint" class="motor" ctrllimited="true" ctrlrange="-36.0 36.0" gear="1" />
    <motor name="l_ankle_roll_joint_ctrl" joint="l_ankle_roll_joint" class="motor" ctrllimited="true" ctrlrange="-14.0 14.0" gear="1" />
  </actuator>

  <contact>
    <exclude body1="waist_link" body2="waist_yaw_Link" />
    <exclude body1="r_shoulder_roll_Link" body2="r_elbow_yaw_Link" />
    <exclude body1="r_elbow_yaw_Link" body2="r_elbow_pitch_Link" />
    <exclude body1="r_elbow_pitch_Link" body2="r_wrist_pitch_Link" />
    <exclude body1="l_shoulder_roll_Link" body2="l_elbow_yaw_Link" />
    <exclude body1="l_elbow_yaw_Link" body2="l_elbow_pitch_Link" />
    <exclude body1="l_elbow_pitch_Link" body2="l_wrist_pitch_Link" />
    <exclude body1="waist_link" body2="r_hip_pitch_Link" />
    <exclude body1="r_hip_pitch_Link" body2="r_hip_roll_Link" />
    <exclude body1="r_hip_roll_Link" body2="r_hip_yaw_Link" />
    <exclude body1="r_hip_yaw_Link" body2="r_knee_pitch_Link" />
    <exclude body1="waist_link" body2="l_hip_pitch_Link" />
    <exclude body1="l_hip_pitch_Link" body2="l_hip_roll_Link" />
    <exclude body1="l_hip_roll_Link" body2="l_hip_yaw_Link" />
    <exclude body1="l_hip_yaw_Link" body2="l_knee_pitch_Link" />
  </contact>

  <sensor>
    <framepos name="world_site_pos" objtype="site" objname="world_site" />
    <framequat name="world_site_quat" objtype="site" objname="world_site" />
    <framelinvel name="world_site_linvel" objtype="site" objname="world_site" />
    <frameangvel name="world_site_angvel" objtype="site" objname="world_site" />
    <velocimeter name="world_site_vel" site="world_site" />
    <framequat name="orientation" objtype="site" noise="0.001" objname="imu" />
    <gyro name="angular-velocity" site="imu" noise="0.005" cutoff="34.9" />
  </sensor>

  <statistic center="1.0 0.7 1.0" extent="0.8"/>
  <visual>
    <headlight diffuse="0.6 0.6 0.6" ambient="0.3 0.3 0.3" specular="0 0 0" />
    <rgba haze="0.15 0.25 0.35 1" />
    <global azimuth="-130" elevation="-20" />
  </visual>
  <worldbody>
    <light pos="0 0 1.5" dir="0 0 -1" directional="true" />
    <geom name="floor" size="0 0 0.05" type="plane" material="groundplane" />
  </worldbody>
</mujoco>