<?xml version="1.0" encoding="utf-8"?>
<robot name="DM8006">

  <!-- Base link (fixed) -->
  <link name="l_hip_roll_link">
    <inertial>
      <origin xyz="0 0 0" rpy="0 0 0" />
      <mass value="0.4813" />
      <inertia
        ixx="0.0002035"
        ixy="0"
        ixz="0"
        iyy="0.00026097"
        iyz="0"
        izz="0.00041524" />
    </inertial>
    <visual>
      <origin xyz="0 0 0" rpy="0 0 0" />
      <geometry>
        <box size="0.1 0.1 0.1"/>
      </geometry>
      <material name="grey">
        <color rgba="0.5 0.5 0.5 1" />
      </material>
    </visual>
    <collision>
      <origin xyz="0 0 0" rpy="0 0 0" />
      <geometry>
        <box size="0.1 0.1 0.1"/>
      </geometry>
    </collision>
  </link>

  <!-- Moving link -->
  <link name="l_hip_yaw_link">
    <inertial>
      <origin xyz="0 0 0.05" rpy="0 0 0" />
      <mass value="0.1" />
      <inertia
        ixx="0.0001"
        ixy="0"
        ixz="0"
        iyy="0.0001"
        iyz="0"
        izz="0.00005" />
    </inertial>
    <visual>
      <origin xyz="0 0 0.05" rpy="0 0 0" />
      <geometry>
        <cylinder radius="0.03" length="0.1"/>
      </geometry>
      <material name="blue">
        <color rgba="0.2 0.2 0.8 1" />
      </material>
    </visual>
    <collision>
      <origin xyz="0 0 0.05" rpy="0 0 0" />
      <geometry>
        <cylinder radius="0.03" length="0.1"/>
      </geometry>
    </collision>
  </link>

  <!-- Joint -->
  <joint name="l_hip_yaw_joint" type="revolute">
    <origin xyz="0 0 0.1" rpy="0 0 0" />
    <parent link="l_hip_roll_link" />
    <child link="l_hip_yaw_link" />
    <axis xyz="0 0 1" />
    <limit
      lower="-1.57"
      upper="1.57"
      effort="14"
      velocity="12.56" />
    <dynamics damping="0.1" friction="0.01" />
  </joint>

</robot>
