<?xml version="1.0" encoding="utf-8"?>
<robot name="DM8006">

  <link
    name="l_hip_roll_link">
    <inertial>
      <origin
        xyz="-0.00066826 -0.00074475 0.00076094"
        rpy="0 0 0" />
      <mass
        value="0.4813" />
      <inertia
        ixx="0.0002035"
        ixy="-1.0034E-05"
        ixz="1.8707E-06"
        iyy="0.00026097"
        iyz="2.2574E-06"
        izz="0.00041524" />
    </inertial>
    <visual>
      <origin
        xyz="0 0 0"
        rpy="0 0 0" />
      <geometry>
        <mesh
          filename="../meshes/left_hip_roll_link.STL" />
      </geometry>
      <material
        name="">
        <color
          rgba="0.89804 0.91765 0.92941 1" />
      </material>
    </visual>
    <collision>
      <origin
        xyz="0 0 0"
        rpy="0 0 0" />
      <geometry>
        <mesh
          filename="../meshes/left_hip_roll_link.STL" />
      </geometry>
    </collision>
  </link>
  <link
    name="l_hip_yaw_link">
    <inertial>
      <origin
        xyz="0 0 0"
        rpy="0 0 0" />
      <mass
        value="0.00001" />
      <inertia
        ixx="0.00001"
        ixy="0"
        ixz="0"
        iyy="0.00001"
        iyz="0"
        izz="0.00001" />
    </inertial>
    <visual>
      <origin
        xyz="0 0 0"
        rpy="0 0 0" />
      <geometry>
        <mesh
          filename="../meshes/left_hip_yaw_link.STL" />
      </geometry>
      <material
        name="">
        <color
          rgba="0.89804 0.91765 0.92941 1" />
      </material>
    </visual>
    <collision>
      <origin
        xyz="0 0 0"
        rpy="0 0 0" />
      <geometry>
        <mesh
          filename="../meshes/left_hip_yaw_link.STL" />
      </geometry>
    </collision>
  </link>
  <joint
    name="l_hip_yaw_joint"
    type="revolute">
    <origin
      xyz="0 0 0"
      rpy="0 0 0" />
    <parent
      link="l_hip_roll_link" />
    <child
      link="l_hip_yaw_link" />
    <axis
      xyz="0 0 1" />
    <limit
      lower="-1.57"
      upper="1.57"
      effort="14"
      velocity="12.56" />
    <dynamics
      damping="0"
      friction="0" />
  </joint>

</robot>