<?xml version="1.0" encoding="utf-8"?>
<!-- This URDF was automatically created by SolidWorks to URDF Exporter! Originally created by Stephen Brawner (brawner@gmail.com) 
     Commit Version: 1.6.0-4-g7f85cfe  Build Version: 1.6.7995.38578
     For more information, please see http://wiki.ros.org/sw_urdf_exporter -->
<robot
  name="atomV3_description">
  <link
    name="base_link">
    <inertial>
      <origin
        xyz="-0.0052794 -5.3872E-05 0.0082794"
        rpy="0 0 0" />
      <mass
        value="4.2175" />
      <inertia
        ixx="0.0094218"
        ixy="-1.2013E-07"
        ixz="-8.5019E-05"
        iyy="0.0052827"
        iyz="-3.4806E-07"
        izz="0.006592" />
    </inertial>
    <visual>
      <origin
        xyz="0 0 0"
        rpy="0 0 0" />
      <geometry>
        <mesh
          filename="../meshes/base_link.STL" />
      </geometry>
      <material
        name="">
        <color
          rgba="0.99608 0.99608 1 1" />
      </material>
    </visual>
    <collision>
      <origin xyz="0.01 0 -0.025" rpy="0 0 0"/>
      <geometry>
        <box size="0.08 0.19 0.075"/>
      </geometry>
    </collision>
    <collision>
      <origin xyz="-0.0075 0 0.065" rpy="0 0 0"/>
      <geometry>
        <box size="0.11 0.15 0.075"/>
      </geometry>
    </collision>
  </link>
  <link
    name="left_hip_roll_link">
    <inertial>
      <origin
        xyz="-0.00066826 -0.00074475 0.00076094"
        rpy="0 0 0" />
      <mass
        value="0.4813" />
      <inertia
        ixx="0.0002035"
        ixy="-1.0034E-05"
        ixz="1.8707E-06"
        iyy="0.00026097"
        iyz="2.2574E-06"
        izz="0.00041524" />
    </inertial>
    <visual>
      <origin
        xyz="0 0 0"
        rpy="0 0 0" />
      <geometry>
        <mesh
          filename="../meshes/left_hip_roll_link.STL" />
      </geometry>
      <material
        name="">
        <color
          rgba="0.89804 0.91765 0.92941 1" />
      </material>
    </visual>
    <collision>
      <origin
        xyz="0 0 0"
        rpy="0 0 0" />
      <geometry>
        <mesh
          filename="../meshes/left_hip_roll_link.STL" />
      </geometry>
    </collision>
  </link>
  <joint
    name="left_hip_roll_joint"
    type="fixed">
    <origin
      xyz="0 0.0585 -0.133"
      rpy="0 0 0" />
    <parent
      link="base_link" />
    <child
      link="left_hip_roll_link" />
    <axis
      xyz="1 0 0" />
    <limit
      lower="-0.405"
      upper="0.457"
      effort="20"
      velocity="10" />
    <dynamics
      damping="0"
      friction="0" />
  </joint>
  <link
    name="left_hip_yaw_link">
    <inertial>
      <origin
        xyz="-4.3756E-05 -0.01523 -0.071402"
        rpy="0 0 0" />
      <mass
        value="0.69496" />
      <inertia
        ixx="0.00054582"
        ixy="-6.66E-07"
        ixz="-1.5037E-07"
        iyy="0.00088245"
        iyz="-3.5255E-05"
        izz="0.00049906" />
    </inertial>
    <visual>
      <origin
        xyz="0 0 0"
        rpy="0 0 0" />
      <geometry>
        <mesh
          filename="../meshes/left_hip_yaw_link.STL" />
      </geometry>
      <material
        name="">
        <color
          rgba="0.89804 0.91765 0.92941 1" />
      </material>
    </visual>
    <collision>
      <origin
        xyz="0 0 0"
        rpy="0 0 0" />
      <geometry>
        <mesh
          filename="../meshes/left_hip_yaw_link.STL" />
      </geometry>
    </collision>
  </link>
  <joint
    name="left_hip_yaw_joint"
    type="fixed">
    <origin
      xyz="0 0 0"
      rpy="0 0 0" />
    <parent
      link="left_hip_roll_link" />
    <child
      link="left_hip_yaw_link" />
    <axis
      xyz="0 0 1" />
    <limit
      lower="-1.44"
      upper="1.44"
      effort="11"
      velocity="12.5" />
    <dynamics
      damping="0"
      friction="0" />
  </joint>
  <link
    name="left_thigh_link">
    <inertial>
      <origin
        xyz="0.0009729 0.013226 -0.033607"
        rpy="0 0 0" />
      <mass
        value="0.9956" />
      <inertia
        ixx="0.0019508"
        ixy="1.1373E-07"
        ixz="4.04E-05"
        iyy="0.0025556"
        iyz="9.6383E-06"
        izz="0.00071679" />
    </inertial>
    <visual>
      <origin
        xyz="0 0 0"
        rpy="0 0 0" />
      <geometry>
        <mesh
          filename="../meshes/left_thigh_link.STL" />
      </geometry>
      <material
        name="">
        <color
          rgba="0.89804 0.91765 0.92941 1" />
      </material>
    </visual>
    <collision>
      <origin
        xyz="0 0 0"
        rpy="0 0 0" />
      <geometry>
        <mesh
          filename="../meshes/left_thigh_link.STL" />
      </geometry>
    </collision>
  </link>
  <joint
    name="left_hip_pitch_joint"
    type="fixed">
    <origin
      xyz="0 0.0165 -0.0762"
      rpy="0 0 0" />
    <parent
      link="left_hip_yaw_link" />
    <child
      link="left_thigh_link" />
    <axis
      xyz="0 1 0" />
    <limit
      lower="-1.57"
      upper="1.57"
      effort="20"
      velocity="10" />
    <dynamics
      damping="0"
      friction="0" />
  </joint>
  <link
    name="left_calf_link">
    <inertial>
      <origin
        xyz="-0.0014421 0.0015552 -0.076072"
        rpy="0 0 0" />
      <mass
        value="0.64386" />
      <inertia
        ixx="0.0014658"
        ixy="-2.5313E-06"
        ixz="-1.2557E-05"
        iyy="0.0016639"
        iyz="1.8574E-05"
        izz="0.00025829" />
    </inertial>
    <visual>
      <origin
        xyz="0 0 0"
        rpy="0 0 0" />
      <geometry>
        <mesh
          filename="../meshes/left_calf_link.STL" />
      </geometry>
      <material
        name="">
        <color
          rgba="0.89804 0.91765 0.92941 1" />
      </material>
    </visual>
    <collision>
      <origin
        xyz="0 0 0"
        rpy="0 0 0" />
      <geometry>
        <mesh
          filename="../meshes/left_calf_link.STL" />
      </geometry>
    </collision>
  </link>
  <joint
    name="left_knee_joint"
    type="fixed">
    <origin
      xyz="0 0 -0.1666"
      rpy="0 0 0" />
    <parent
      link="left_thigh_link" />
    <child
      link="left_calf_link" />
    <axis
      xyz="0 1 0" />
    <limit
      lower="0"
      upper="2.094"
      effort="27.2"
      velocity="7.6" />
    <dynamics
      damping="0"
      friction="0" />
  </joint>
  <link
    name="left_foot_link">
    <inertial>
      <origin
        xyz="0.025032 -0.001514 -0.023354"
        rpy="0 0 0" />
      <mass
        value="0.12846" />
      <inertia
        ixx="2.5025E-05"
        ixy="7.2282E-07"
        ixz="1.4497E-06"
        iyy="0.00018017"
        iyz="-9.0395E-08"
        izz="0.00018147" />
    </inertial>
    <visual>
      <origin
        xyz="0 0 0"
        rpy="0 0 0" />
      <geometry>
        <mesh
          filename="../meshes/left_foot_link.STL" />
      </geometry>
      <material
        name="">
        <color
          rgba="0.89804 0.91765 0.92941 1" />
      </material>
    </visual>
    <collision>
      <origin
        xyz="0 0 0"
        rpy="0 0 0" />
      <geometry>
        <mesh
          filename="../meshes/left_foot_link.STL" />
      </geometry>
    </collision>
  </link>
  <joint
    name="left_ankle_joint"
    type="fixed">
    <origin
      xyz="0 0 -0.19"
      rpy="0 0 0" />
    <parent
      link="left_calf_link" />
    <child
      link="left_foot_link" />
    <axis
      xyz="0 1 0" />
    <limit
      lower="-1.222"
      upper="0.523"
      effort="11"
      velocity="12.5" />
  </joint>
  <link
    name="right_hip_roll_link">
    <inertial>
      <origin
        xyz="-0.00071646 0.00088979 0.00076094"
        rpy="0 0 0" />
      <mass
        value="0.4813" />
      <inertia
        ixx="0.0002032"
        ixy="9.7417E-06"
        ixz="1.888E-06"
        iyy="0.00026126"
        iyz="-2.2512E-06"
        izz="0.00041524" />
    </inertial>
    <visual>
      <origin
        xyz="0 0 0"
        rpy="0 0 0" />
      <geometry>
        <mesh
          filename="../meshes/right_hip_roll_link.STL" />
      </geometry>
      <material
        name="">
        <color
          rgba="0.89804 0.91765 0.92941 1" />
      </material>
    </visual>
    <collision>
      <origin
        xyz="0 0 0"
        rpy="0 0 0" />
      <geometry>
        <mesh
          filename="../meshes/right_hip_roll_link.STL" />
      </geometry>
    </collision>
  </link>
  <joint
    name="right_hip_roll_joint"
    type="fixed">
    <origin
      xyz="0 -0.0585 -0.133"
      rpy="0 0 0" />
    <parent
      link="base_link" />
    <child
      link="right_hip_roll_link" />
    <axis
      xyz="1 0 0" />
    <limit
      lower="-0.457"
      upper="0.405"
      effort="20"
      velocity="10" />
    <dynamics
      damping="0"
      friction="0" />
  </joint>
  <link
    name="right_hip_yaw_link">
    <inertial>
      <origin
        xyz="4.3782E-05 0.01523 -0.071402"
        rpy="0 0 0" />
      <mass
        value="0.69496" />
      <inertia
        ixx="0.00054582"
        ixy="-6.6649E-07"
        ixz="1.5053E-07"
        iyy="0.00088245"
        iyz="3.5254E-05"
        izz="0.00049906" />
    </inertial>
    <visual>
      <origin
        xyz="0 0 0"
        rpy="0 0 0" />
      <geometry>
        <mesh
          filename="../meshes/right_hip_yaw_link.STL" />
      </geometry>
      <material
        name="">
        <color
          rgba="0.89804 0.91765 0.92941 1" />
      </material>
    </visual>
    <collision>
      <origin
        xyz="0 0 0"
        rpy="0 0 0" />
      <geometry>
        <mesh
          filename="../meshes/right_hip_yaw_link.STL" />
      </geometry>
    </collision>
  </link>
  <joint
    name="right_hip_yaw_joint"
    type="fixed">
    <origin
      xyz="0 0 0"
      rpy="0 0 0" />
    <parent
      link="right_hip_roll_link" />
    <child
      link="right_hip_yaw_link" />
    <axis
      xyz="0 0 1" />
    <limit
      lower="-1.44"
      upper="1.44"
      effort="11"
      velocity="12.5" />
    <dynamics
      damping="0"
      friction="0" />
  </joint>
  <link
    name="right_thigh_link">
    <inertial>
      <origin
        xyz="0.0010329 -0.013226 -0.033605"
        rpy="0 0 0" />
      <mass
        value="0.9956" />
      <inertia
        ixx="0.0019508"
        ixy="1.1882E-06"
        ixz="4.0114E-05"
        iyy="0.0025556"
        iyz="-9.592E-06"
        izz="0.00071677" />
    </inertial>
    <visual>
      <origin
        xyz="0 0 0"
        rpy="0 0 0" />
      <geometry>
        <mesh
          filename="../meshes/right_thigh_link.STL" />
      </geometry>
      <material
        name="">
        <color
          rgba="0.89804 0.91765 0.92941 1" />
      </material>
    </visual>
    <collision>
      <origin
        xyz="0 0 0"
        rpy="0 0 0" />
      <geometry>
        <mesh
          filename="../meshes/right_thigh_link.STL" />
      </geometry>
    </collision>
  </link>
  <joint
    name="right_hip_pitch_joint"
    type="revolute">
    <origin
      xyz="0 -0.0165 -0.0762"
      rpy="0 0 0" />
    <parent
      link="right_hip_yaw_link" />
    <child
      link="right_thigh_link" />
    <axis
      xyz="0 1 0" />
    <limit
      lower="-1.57"
      upper="1.57"
      effort="20"
      velocity="10" />
    <dynamics
      damping="0"
      friction="0" />
  </joint>
  <link
    name="right_calf_link">
    <inertial>
      <origin
        xyz="-0.001437 -0.0015552 -0.076073"
        rpy="0 0 0" />
      <mass
        value="0.64387" />
      <inertia
        ixx="0.0014658"
        ixy="2.5424E-06"
        ixz="-1.265E-05"
        iyy="0.0016639"
        iyz="-1.8571E-05"
        izz="0.00025827" />
    </inertial>
    <visual>
      <origin
        xyz="0 0 0"
        rpy="0 0 0" />
      <geometry>
        <mesh
          filename="../meshes/right_calf_link.STL" />
      </geometry>
      <material
        name="">
        <color
          rgba="0.89804 0.91765 0.92941 1" />
      </material>
    </visual>
    <collision>
      <origin
        xyz="0 0 0"
        rpy="0 0 0" />
      <geometry>
        <mesh
          filename="../meshes/right_calf_link.STL" />
      </geometry>
    </collision>
  </link>
  <joint
    name="right_knee_joint"
    type="revolute">
    <origin
      xyz="0 0 -0.1666"
      rpy="0 0 0" />
    <parent
      link="right_thigh_link" />
    <child
      link="right_calf_link" />
    <axis
      xyz="0 1 0" />
    <limit
      lower="0"
      upper="2.094"
      effort="27.2"
      velocity="7.6" />
    <dynamics
      damping="0"
      friction="0" />
  </joint>
  <link
    name="right_foot_link">
    <inertial>
      <origin
        xyz="0.025032 0.0014641 -0.023354"
        rpy="0 0 0" />
      <mass
        value="0.12846" />
      <inertia
        ixx="2.5025E-05"
        ixy="-7.2295E-07"
        ixz="1.4497E-06"
        iyy="0.00018017"
        iyz="9.0395E-08"
        izz="0.00018146" />
    </inertial>
    <visual>
      <origin
        xyz="0 0 0"
        rpy="0 0 0" />
      <geometry>
        <mesh
          filename="../meshes/right_foot_link.STL" />
      </geometry>
      <material
        name="">
        <color
          rgba="0.89804 0.91765 0.92941 1" />
      </material>
    </visual>
    <collision>
      <origin
        xyz="0 0 0"
        rpy="0 0 0" />
      <geometry>
        <mesh
          filename="../meshes/right_foot_link.STL" />
      </geometry>
    </collision>
  </link>
  <joint
    name="right_ankle_joint"
    type="revolute">
    <origin
      xyz="0 0 -0.19"
      rpy="0 0 0" />
    <parent
      link="right_calf_link" />
    <child
      link="right_foot_link" />
    <axis
      xyz="0 1 0" />
    <limit
      lower="-1.222"
      upper="0.523"
      effort="11"
      velocity="12.5" />
    <dynamics
      damping="0"
      friction="0" />
  </joint>
  <link
    name="left_shoulder_pitch_link">
    <inertial>
      <origin
        xyz="0.0015853 0.032976 7.5053E-07"
        rpy="0 0 0" />
      <mass
        value="0.23276" />
      <inertia
        ixx="6.3504E-05"
        ixy="-3.0774E-06"
        ixz="-3.4878E-10"
        iyy="6.9097E-05"
        iyz="2.3822E-10"
        izz="6.9403E-05" />
    </inertial>
    <visual>
      <origin
        xyz="0 0 0"
        rpy="0 0 0" />
      <geometry>
        <mesh
          filename="../meshes/left_shoulder_pitch_link.STL" />
      </geometry>
      <material
        name="">
        <color
          rgba="0.89804 0.91765 0.92941 1" />
      </material>
    </visual>
    <collision>
      <origin
        xyz="0 0 0"
        rpy="0 0 0" />
      <geometry>
        <mesh
          filename="../meshes/left_shoulder_pitch_link.STL" />
      </geometry>
    </collision>
  </link>
  <joint
    name="left_shoulder_pitch_joint"
    type="fixed">
    <origin
      xyz="0.001 0.09575 0.073"
      rpy="0 0 0" />
    <parent
      link="base_link" />
    <child
      link="left_shoulder_pitch_link" />
    <axis
      xyz="0 1 0" />
    <limit
      lower="-3.14"
      upper="1.57"
      effort="5.5"
      velocity="10" />
    <dynamics
      damping="0"
      friction="0" />
  </joint>
  <link
    name="left_shoulder_roll_link">
    <inertial>
      <origin
        xyz="-0.018681 -8.7233E-07 -0.046738"
        rpy="0 0 0" />
      <mass
        value="0.23973" />
      <inertia
        ixx="7.2323E-05"
        ixy="1.7796E-09"
        ixz="-3.6355E-06"
        iyy="7.4766E-05"
        iyz="1.5495E-09"
        izz="6.8891E-05" />
    </inertial>
    <visual>
      <origin
        xyz="0 0 0"
        rpy="0 0 0" />
      <geometry>
        <mesh
          filename="../meshes/left_shoulder_roll_link.STL" />
      </geometry>
      <material
        name="">
        <color
          rgba="0.89804 0.91765 0.92941 1" />
      </material>
    </visual>
    <collision>
      <origin
        xyz="0 0 0"
        rpy="0 0 0" />
      <geometry>
        <mesh
          filename="../meshes/left_shoulder_roll_link.STL" />
      </geometry>
    </collision>
  </link>
  <joint
    name="left_shoulder_roll_joint"
    type="fixed">
    <origin
      xyz="0.022 0.0365 0"
      rpy="0 0 0" />
    <parent
      link="left_shoulder_pitch_link" />
    <child
      link="left_shoulder_roll_link" />
    <axis
      xyz="1 0 0" />
    <limit
      lower="0"
      upper="3.14"
      effort="5.5"
      velocity="10" />
    <dynamics
      damping="0"
      friction="0" />
  </joint>
  <link
    name="left_shoulder_yaw_link">
    <inertial>
      <origin
        xyz="-7.5053E-07 0.0015853 -0.032976"
        rpy="0 0 0" />
      <mass
        value="0.23276" />
      <inertia
        ixx="6.9403E-05"
        ixy="3.4878E-10"
        ixz="2.3822E-10"
        iyy="6.3504E-05"
        iyz="3.0774E-06"
        izz="6.9097E-05" />
    </inertial>
    <visual>
      <origin
        xyz="0 0 0"
        rpy="0 0 0" />
      <geometry>
        <mesh
          filename="../meshes/left_shoulder_yaw_link.STL" />
      </geometry>
      <material
        name="">
        <color
          rgba="0.89804 0.91765 0.92941 1" />
      </material>
    </visual>
    <collision>
      <origin
        xyz="0 0 0"
        rpy="0 0 0" />
      <geometry>
        <mesh
          filename="../meshes/left_shoulder_yaw_link.STL" />
      </geometry>
    </collision>
  </link>
  <joint
    name="left_shoulder_yaw_joint"
    type="fixed">
    <origin
      xyz="-0.022 0 -0.075"
      rpy="0 0 0" />
    <parent
      link="left_shoulder_roll_link" />
    <child
      link="left_shoulder_yaw_link" />
    <axis
      xyz="0 0 1" />
    <limit
      lower="-1.57"
      upper="1.57"
      effort="5.5"
      velocity="10" />
    <dynamics
      damping="0"
      friction="0" />
  </joint>
  <link
    name="left_elbow_link">
    <inertial>
      <origin
        xyz="0.082431 -0.017191 0.00015682"
        rpy="0 0 0" />
      <mass
        value="0.075891" />
      <inertia
        ixx="1.5323E-05"
        ixy="2.8448E-05"
        ixz="-7.1075E-09"
        iyy="0.00017186"
        iyz="-3.4451E-09"
        izz="0.00018124" />
    </inertial>
    <visual>
      <origin
        xyz="0 0 0"
        rpy="0 0 0" />
      <geometry>
        <mesh
          filename="../meshes/left_elbow_link.STL" />
      </geometry>
      <material
        name="">
        <color
          rgba="0.89804 0.91765 0.92941 1" />
      </material>
    </visual>
    <collision>
      <origin
        xyz="0 0 0"
        rpy="0 0 0" />
      <geometry>
        <mesh
          filename="../meshes/left_elbow_link.STL" />
      </geometry>
    </collision>
  </link>
  <joint
    name="left_elbow_joint"
    type="fixed">
    <origin
      xyz="0 0.022 -0.0365"
      rpy="0 0 0" />
    <parent
      link="left_shoulder_yaw_link" />
    <child
      link="left_elbow_link" />
    <axis
      xyz="0 1 0" />
    <limit
      lower="-0.2"
      upper="1.57"
      effort="5.5"
      velocity="10" />
    <dynamics
      damping="0"
      friction="0" />
  </joint>
  <link
    name="right_shoulder_pitch_link">
    <inertial>
      <origin
        xyz="0.0015853 -0.032976 -7.5053E-07"
        rpy="0 0 0" />
      <mass
        value="0.23276" />
      <inertia
        ixx="6.3504E-05"
        ixy="3.0774E-06"
        ixz="3.4878E-10"
        iyy="6.9097E-05"
        iyz="2.3822E-10"
        izz="6.9403E-05" />
    </inertial>
    <visual>
      <origin
        xyz="0 0 0"
        rpy="0 0 0" />
      <geometry>
        <mesh
          filename="../meshes/right_shoulder_pitch_link.STL" />
      </geometry>
      <material
        name="">
        <color
          rgba="0.89804 0.91765 0.92941 1" />
      </material>
    </visual>
    <collision>
      <origin
        xyz="0 0 0"
        rpy="0 0 0" />
      <geometry>
        <mesh
          filename="../meshes/right_shoulder_pitch_link.STL" />
      </geometry>
    </collision>
  </link>
  <joint
    name="right_shoulder_pitch_joint"
    type="fixed">
    <origin
      xyz="0.001 -0.09575 0.073"
      rpy="0 0 0" />
    <parent
      link="base_link" />
    <child
      link="right_shoulder_pitch_link" />
    <axis
      xyz="0 1 0" />
    <limit
      lower="-3.14"
      upper="1.57"
      effort="5.5"
      velocity="10" />
    <dynamics
      damping="0"
      friction="0" />
  </joint>
  <link
    name="right_shoulder_roll_link">
    <inertial>
      <origin
        xyz="-0.018681 -8.7233E-07 -0.046738"
        rpy="0 0 0" />
      <mass
        value="0.23973" />
      <inertia
        ixx="7.2323E-05"
        ixy="1.7796E-09"
        ixz="-3.6355E-06"
        iyy="7.4766E-05"
        iyz="1.5495E-09"
        izz="6.8891E-05" />
    </inertial>
    <visual>
      <origin
        xyz="0 0 0"
        rpy="0 0 0" />
      <geometry>
        <mesh
          filename="../meshes/right_shoulder_roll_link.STL" />
      </geometry>
      <material
        name="">
        <color
          rgba="0.89804 0.91765 0.92941 1" />
      </material>
    </visual>
    <collision>
      <origin
        xyz="0 0 0"
        rpy="0 0 0" />
      <geometry>
        <mesh
          filename="../meshes/right_shoulder_roll_link.STL" />
      </geometry>
    </collision>
  </link>
  <joint
    name="right_shoulder_roll_joint"
    type="fixed">
    <origin
      xyz="0.022 -0.0365 0"
      rpy="0 0 0" />
    <parent
      link="right_shoulder_pitch_link" />
    <child
      link="right_shoulder_roll_link" />
    <axis
      xyz="1 0 0" />
    <limit
      lower="-3.14"
      upper="0"
      effort="5.5"
      velocity="10" />
    <dynamics
      damping="0"
      friction="0" />
  </joint>
  <link
    name="right_shoulder_yaw_link">
    <inertial>
      <origin
        xyz="7.5053E-07 -0.0015853 -0.032976"
        rpy="0 0 0" />
      <mass
        value="0.23276" />
      <inertia
        ixx="6.9403E-05"
        ixy="3.4878E-10"
        ixz="-2.3822E-10"
        iyy="6.3504E-05"
        iyz="-3.0774E-06"
        izz="6.9097E-05" />
    </inertial>
    <visual>
      <origin
        xyz="0 0 0"
        rpy="0 0 0" />
      <geometry>
        <mesh
          filename="../meshes/right_shoulder_yaw_link.STL" />
      </geometry>
      <material
        name="">
        <color
          rgba="0.89804 0.91765 0.92941 1" />
      </material>
    </visual>
    <collision>
      <origin
        xyz="0 0 0"
        rpy="0 0 0" />
      <geometry>
        <mesh
          filename="../meshes/right_shoulder_yaw_link.STL" />
      </geometry>
    </collision>
  </link>
  <joint
    name="right_shoulder_yaw_joint"
    type="fixed">
    <origin
      xyz="-0.022 0 -0.075"
      rpy="0 0 0" />
    <parent
      link="right_shoulder_roll_link" />
    <child
      link="right_shoulder_yaw_link" />
    <axis
      xyz="0 0 1" />
    <limit
      lower="-1.57"
      upper="1.57"
      effort="5.5"
      velocity="10" />
    <dynamics
      damping="0"
      friction="0" />
  </joint>
  <link
    name="right_elbow_link">
    <inertial>
      <origin
        xyz="0.082431 0.017191 -0.00015682"
        rpy="0 0 0" />
      <mass
        value="0.075891" />
      <inertia
        ixx="1.5323E-05"
        ixy="-2.8448E-05"
        ixz="7.107E-09"
        iyy="0.00017186"
        iyz="-3.4826E-09"
        izz="0.00018124" />
    </inertial>
    <visual>
      <origin
        xyz="0 0 0"
        rpy="0 0 0" />
      <geometry>
        <mesh
          filename="../meshes/right_elbow_link.STL" />
      </geometry>
      <material
        name="">
        <color
          rgba="0.89804 0.91765 0.92941 1" />
      </material>
    </visual>
    <collision>
      <origin
        xyz="0 0 0"
        rpy="0 0 0" />
      <geometry>
        <mesh
          filename="../meshes/right_elbow_link.STL" />
      </geometry>
    </collision>
  </link>
  <joint
    name="right_elbow_joint"
    type="fixed">
    <origin
      xyz="0 -0.022 -0.0365"
      rpy="0 0 0" />
    <parent
      link="right_shoulder_yaw_link" />
    <child
      link="right_elbow_link" />
    <axis
      xyz="0 1 0" />
    <limit
      lower="-0.2"
      upper="1.57"
      effort="5.5"
      velocity="10" />
    <dynamics
      damping="0"
      friction="0" />
  </joint>
</robot>