<?xml version="1.0"?>
<robot name="Y1_1">

  <link name="waist_link">
    <visual>
      <origin xyz="0.0000 0.0000 0.0000" rpy="0.0000 0.0000 0.0000" />
      <geometry>
        <mesh filename="../meshes/waist_link.STL" />
      </geometry>
      <material name="waist_link_mat">
        <color rgba="0.5 0.5 0.5 1.0"/>
      </material>
    </visual>
    <collision>
      <origin xyz="0.0000 0.0000 0.0600" rpy="0.0000 0.0000 0.0000" />
      <geometry>
        <sphere radius="0.0600" />
      </geometry>
    </collision>
    <inertial>
      <origin xyz="0.0013 0.0000 0.0572" rpy="0.0000 0.0000 0.0000" />
      <mass value="1.44414585717254" />
      <inertia ixx="0.0040" ixy="0.0000" ixz="0.0000" iyy="0.0029" iyz="0.0000" izz="0.0027" />
    </inertial>
  </link>

  <link name="waist_yaw_Link">
    <visual>
      <origin xyz="0.0000 0.0000 0.0000" rpy="0.0000 0.0000 0.0000" />
      <geometry>
        <mesh filename="../meshes/waist_yaw_Link.STL" />
      </geometry>
      <material name="waist_yaw_Link_mat">
        <color rgba="0.5 0.5 0.5 1.0"/>
      </material>
    </visual>
    <collision>
      <origin xyz="0.0000 0.0000 0.1500" rpy="0.0000 0.0000 0.0000" />
      <geometry>
        <box size="0.0600 0.1500 0.3000" />
      </geometry>
    </collision>
    <inertial>
      <origin xyz="-0.0048 -0.0001 0.1411" rpy="0.0000 0.0000 0.0000" />
      <mass value="0.000" />
      <inertia ixx="0.000" ixy="0.0000" ixz="0.0000" iyy="0.0000" iyz="0.0000" izz="0.0000" />
    </inertial>
  </link>

  <joint name="waist_yaw_joint" type="revolute">
    <parent link="waist_link" />
    <child link="waist_yaw_Link" />
    <origin xyz="0.0014 0.0000 0.1350" rpy="0.0000 0.0000 0.0000" />
    <axis xyz="0.0000 0.0000 1.0000" />
    <limit lower="-2.5307274153917776" upper="2.5307274153917776" effort="36.0" velocity="50" />
    <hardware>
      <motorType>None</motorType>
      <motorDirection>1</motorDirection>
      <armature>0</armature>
    </hardware>
  </joint>


</robot>